Workbook

Sheet PALLET SHEET
A1: PANEL MODEL | B1: 200WT
A2: QUANTITY: | B2: 25 | C2: WEIGHT (lbs): | D2: 150
A3: Josh Atwood Future Solutions Inc 2616 Glenview Dr, Elkhart, IN 46514 | B3: 200WT2192025-18 | F3: PACKOUT DATE: | G3: 46007
C4: Pm(W) | D4: Isc(A) | E4: Voc(V) | F4: Ipm(A) | G4: Vpm(V) | H4: FF (%)
A5: 1 | C5: =VLOOKUP(B5,DATA!$B$2:$AA$785292,7,FALSE) -> #N/A | D5: =VLOOKUP(B5,DATA!$B$2:$AA$785292,8,FALSE) -> #N/A | E5: =VLOOKUP(B5,DATA!$B$2:$AA$785292,9,FALSE) -> #N/A | F5: =VLOOKUP(B5,DATA!$B$2:$AA$785292,10,FALSE) -> #N/A | G5: =VLOOKUP(B5,DATA!$B$2:$AA$785292,11,FALSE) -> #N/A | H5: =VLOOKUP(B5,DATA!#REF!,7,FALSE) -> #ERROR!
A6: 2 | C6: =VLOOKUP(B6,DATA!$B$2:$AA$785292,7,FALSE) -> #N/A | D6: =VLOOKUP(B6,DATA!$B$2:$AA$785292,8,FALSE) -> #N/A | E6: =VLOOKUP(B6,DATA!$B$2:$AA$785292,9,FALSE) -> #N/A | F6: =VLOOKUP(B6,DATA!$B$2:$AA$785292,10,FALSE) -> #N/A | G6: =VLOOKUP(B6,DATA!$B$2:$AA$785292,11,FALSE) -> #N/A
A7: 3 | C7: =VLOOKUP(B7,DATA!$B$2:$AA$785292,7,FALSE) -> #N/A | D7: =VLOOKUP(B7,DATA!$B$2:$AA$785292,8,FALSE) -> #N/A | E7: =VLOOKUP(B7,DATA!$B$2:$AA$785292,9,FALSE) -> #N/A | F7: =VLOOKUP(B7,DATA!$B$2:$AA$785292,10,FALSE) -> #N/A | G7: =VLOOKUP(B7,DATA!$B$2:$AA$785292,11,FALSE) -> #N/A
A8: 4 | C8: =VLOOKUP(B8,DATA!$B$2:$AA$785292,7,FALSE) -> #N/A | D8: =VLOOKUP(B8,DATA!$B$2:$AA$785292,8,FALSE) -> #N/A | E8: =VLOOKUP(B8,DATA!$B$2:$AA$785292,9,FALSE) -> #N/A | F8: =VLOOKUP(B8,DATA!$B$2:$AA$785292,10,FALSE) -> #N/A | G8: =VLOOKUP(B8,DATA!$B$2:$AA$785292,11,FALSE) -> #N/A
A9: 5 | C9: =VLOOKUP(B9,DATA!$B$2:$AA$785292,7,FALSE) -> #N/A | D9: =VLOOKUP(B9,DATA!$B$2:$AA$785292,8,FALSE) -> #N/A | E9: =VLOOKUP(B9,DATA!$B$2:$AA$785292,9,FALSE) -> #N/A | F9: =VLOOKUP(B9,DATA!$B$2:$AA$785292,10,FALSE) -> #N/A | G9: =VLOOKUP(B9,DATA!$B$2:$AA$785292,11,FALSE) -> #N/A
A10: 6 | C10: =VLOOKUP(B10,DATA!$B$2:$AA$785292,7,FALSE) -> #N/A | D10: =VLOOKUP(B10,DATA!$B$2:$AA$785292,8,FALSE) -> #N/A | E10: =VLOOKUP(B10,DATA!$B$2:$AA$785292,9,FALSE) -> #N/A | F10: =VLOOKUP(B10,DATA!$B$2:$AA$785292,10,FALSE) -> #N/A | G10: =VLOOKUP(B10,DATA!$B$2:$AA$785292,11,FALSE) -> #N/A
A11: 7 | C11: =VLOOKUP(B11,DATA!$B$2:$AA$785292,7,FALSE) -> #N/A | D11: =VLOOKUP(B11,DATA!$B$2:$AA$785292,8,FALSE) -> #N/A | E11: =VLOOKUP(B11,DATA!$B$2:$AA$785292,9,FALSE) -> #N/A | F11: =VLOOKUP(B11,DATA!$B$2:$AA$785292,10,FALSE) -> #N/A | G11: =VLOOKUP(B11,DATA!$B$2:$AA$785292,11,FALSE) -> #N/A
A12: 8 | C12: =VLOOKUP(B12,DATA!$B$2:$AA$785292,7,FALSE) -> #N/A | D12: =VLOOKUP(B12,DATA!$B$2:$AA$785292,8,FALSE) -> #N/A | E12: =VLOOKUP(B12,DATA!$B$2:$AA$785292,9,FALSE) -> #N/A | F12: =VLOOKUP(B12,DATA!$B$2:$AA$785292,10,FALSE) -> #N/A | G12: =VLOOKUP(B12,DATA!$B$2:$AA$785292,11,FALSE) -> #N/A
A13: 9 | C13: =VLOOKUP(B13,DATA!$B$2:$AA$785292,7,FALSE) -> #N/A | D13: =VLOOKUP(B13,DATA!$B$2:$AA$785292,8,FALSE) -> #N/A | E13: =VLOOKUP(B13,DATA!$B$2:$AA$785292,9,FALSE) -> #N/A | F13: =VLOOKUP(B13,DATA!$B$2:$AA$785292,10,FALSE) -> #N/A | G13: =VLOOKUP(B13,DATA!$B$2:$AA$785292,11,FALSE) -> #N/A
A14: 10 | C14: =VLOOKUP(B14,DATA!$B$2:$AA$785292,7,FALSE) -> #N/A | D14: =VLOOKUP(B14,DATA!$B$2:$AA$785292,8,FALSE) -> #N/A | E14: =VLOOKUP(B14,DATA!$B$2:$AA$785292,9,FALSE) -> #N/A | F14: =VLOOKUP(B14,DATA!$B$2:$AA$785292,10,FALSE) -> #N/A | G14: =VLOOKUP(B14,DATA!$B$2:$AA$785292,11,FALSE) -> #N/A
A15: 11 | C15: =VLOOKUP(B15,DATA!$B$2:$AA$785292,7,FALSE) -> #N/A | D15: =VLOOKUP(B15,DATA!$B$2:$AA$785292,8,FALSE) -> #N/A | E15: =VLOOKUP(B15,DATA!$B$2:$AA$785292,9,FALSE) -> #N/A | F15: =VLOOKUP(B15,DATA!$B$2:$AA$785292,10,FALSE) -> #N/A | G15: =VLOOKUP(B15,DATA!$B$2:$AA$785292,11,FALSE) -> #N/A
A16: 12 | C16: =VLOOKUP(B16,DATA!$B$2:$AA$785292,7,FALSE) -> #N/A | D16: =VLOOKUP(B16,DATA!$B$2:$AA$785292,8,FALSE) -> #N/A | E16: =VLOOKUP(B16,DATA!$B$2:$AA$785292,9,FALSE) -> #N/A | F16: =VLOOKUP(B16,DATA!$B$2:$AA$785292,10,FALSE) -> #N/A | G16: =VLOOKUP(B16,DATA!$B$2:$AA$785292,11,FALSE) -> #N/A
A17: 13 | C17: =VLOOKUP(B17,DATA!$B$2:$AA$785292,7,FALSE) -> #N/A | D17: =VLOOKUP(B17,DATA!$B$2:$AA$785292,8,FALSE) -> #N/A | E17: =VLOOKUP(B17,DATA!$B$2:$AA$785292,9,FALSE) -> #N/A | F17: =VLOOKUP(B17,DATA!$B$2:$AA$785292,10,FALSE) -> #N/A | G17: =VLOOKUP(B17,DATA!$B$2:$AA$785292,11,FALSE) -> #N/A
... A30: 26 | C30: =VLOOKUP(B30,DATA!$B$2:$AA$785292,7,FALSE) -> #N/A | D30: =VLOOKUP(B30,DATA!$B$2:$AA$785292,8,FALSE) -> #N/A | E30: =VLOOKUP(B30,DATA!$B$2:$AA$785292,9,FALSE) -> #N/A | F30: =VLOOKUP(B30,DATA!$B$2:$AA$785292,10,FALSE) -> #N/A | G30: =VLOOKUP(B30,DATA!$B$2:$AA$785292,11,FALSE) -> #N/A
A31: SIGNATURE:_______________________________________________________________________________________ DATE:_____________________________________________________________________

Sheet DATA
A1: SerialNo-SPECIAL CODES | B1: SerialNo | C1: Date | D1: TTime | E1: curveTag | F1: Prefix | G1: Catalogue | H1: Pm(W) | I1: Isc(A) | J1: Voc(V) | K1: Ipm(A) | L1: Vpm(V) | M1: FF | N1: Eff | O1: I.Work | P1: V.Work | Q1: Temp | R1: Rs | S1: Peak | T1: Rsh | U1: Customer | V1: NOTES | W1: adjusted pm | X1: adjusted isc | Y1: adjusted voc | Z1: adjusted imp | AA1: adjusted vpm
B2: =" CRS25WT3607766" -> CRS25WT3607766 | C2: 45950 | D2: 0.98828704 | E2: I->V | F2: 203 | G2: 4 | H2: 203.01877 | I2: 9.6382437 | J2: 24.562885 | K2: 9.8823366 | L2: 20.5436 | M2: 0.85754895 | N2: 9.8768559 | O2: 0 | P2: 0 | Q2: 0.0082509099 | R2: 25 | S2: 0.23738979 | T2: 992.77008 | U2: 343.45685
B3: ="\" -> \ | C3: 45917 | D3: 下午 5:41:27 | E3: I->V | F3: 195 | G3: 4 | H3: 195.73758 | I3: 10.158898 | J3: 24.696564 | K3: 10.441025 | L3: 18.746969 | M3: 0.7801733 | N3: 9.5226259 | O3: 0 | P3: 0 | Q3: 0.011587922 | R3: 25 | S3: 0.27315035 | T3: 1034.4706 | U3: 236.60741
B4: ="22131" -> 22131 | C4: 45943 | D4: 下午 7:30:01 | E4: I->V | F4: 218 | G4: 4 | H4: 218.80389 | I4: 5.6854286 | J4: 49.714924 | K4: 5.1633897 | L4: 42.376019 | M4: 0.77411425 | N4: 10.644801 | O4: 0 | P4: 0 | Q4: 0.011309523 | R4: 25 | S4: 0.6902315 | T4: 998.47144 | U4: 552.15607
B5: ="25WT72M21136" -> 25WT72M21136 | C5: 45930 | D5: 下午 8:52:08 | E5: I->V | F5: 151 | G5: 2 | H5: 151.4178 | I5: 2.8581607 | J5: 49.102501 | K5: 3.8228836 | L5: 39.608269 | M5: 1.0789136 | N5: 7.3664703 | O5: 0 | P5: 0 | Q5: 0.03819938 | R5: 25 | S5: 1.9497621 | T5: 478.22513 | U5: 6108.5688
B6: ="5WT6008473" -> 5WT6008473 | C6: 45911 | D6: 0.98690972 | E6: I->V | F6: 324 | G6: 4 | H6: 324.85849 | I6: 10.202183 | J6: 41.034195 | K6: 9.6544819 | L6: 33.648464 | M6: 0.77598834 | N6: 15.804354 | O6: 0 | P6: 0 | Q6: 0.012619047 | R6: 25 | S6: 0.43894297 | T6: 990.94702 | U6: 2871.7646
B7: ="6" -> 6 | C7: 45953 | D7: 0.85760417 | E7: I->V | F7: 327 | G7: 4 | H7: 327.42892 | I7: 10.286176 | J7: 40.998577 | K7: 9.584012 | L7: 34.164078 | M7: 0.77641571 | N7: 15.929405 | O7: 0 | P7: 0 | Q7: 0.01644849 | R7: 25 | S7: 0.39198598 | T7: 1003.1349 | U7: 910.96405
B8: ="7116" -> 7116 | C8: 45917 | D8: 下午 8:05:57 | E8: I->V | F8: 197 | G8: 4 | H8: 197.16812 | I8: 9.682456 | J8: 24.644239 | K8: 10.072859 | L8: 19.574196 | M8: 0.82629621 | N8: 9.5922222 | O8: 0 | P8: 0 | Q8: 0.013808749 | R8: 25 | S8: 0.3179917 | T8: 1114.7281 | U8: 1018.0636
B9: ="76" -> 76 | C9: 45945 | D9: 0.089884259 | E9: I->V | F9: 455 | G9: 3 | H9: 455.9021 | I9: 11.243464 | J9: 49.652641 | K9: 10.719293 | L9: 42.530987 | M9: 0.81663716 | N9: 22.179621 | O9: 23.09804 | P9: 23.8125 | Q9: 0.45846719 | R9: 998.94257 | S9: 349.83493
B10: ="95" -> 95 | C10: 45917 | D10: 下午 11:31:03 | E10: I->V | F10: 199 | G10: 4 | H10: 199.70497 | I10: 9.6617317 | J10: 24.687002 | K10: 10.16113 | L10: 19.653816 | M10: 0.83727002 | N10: 9.7156391 | O10: 0 | P10: 0 | Q10: 0.015238095 | R10: 25 | S10: 0.31511626 | T10: 1009.218 | U10: 1752.9377
B11: ="CRS22WW7200370" -> CRS22WW7200370 | C11: 45757 | D11: 0.67351852 | E11: I->V | F11: 397 | G11: 4 | H11: 397.25668 | I11: 10.122827 | J11: 50.398441 | K11: 9.4172754 | L11: 42.183826 | M11: 0.77866799 | N11: 242.82193 | O11: 10.127879 | P11: 0.47999999 | Q11: 17.579296 | R11: 0.52985227 | S11: 1000.7766 | T11: 376.63629
B12: ="CRS22WW7200536" -> CRS22WW7200536 | C12: 45757 | D12: 0.67225694 | E12: I->V | F12: 402 | G12: 4 | H12: 402.02148 | I12: 10.14784 | J12: 50.24733 | K12: 9.5287981 | L12: 42.190159 | M12: 0.78842914 | N12: 245.73441 | O12: 10.134128 | P12: 0.47999999 | Q12: 17.50773 | R12: 0.47170857 | S12: 1000.2502 | T12: 1671.7047
B13: ="CRS22WW7201134" -> CRS22WW7201134 | C13: 45757 | D13: 0.66923611 | E13: I->V | F13: 390 | G13: 4 | H13: 390.89026 | I13: 10.126567 | J13: 49.436375 | K13: 9.4263592 | L13: 41.467789 | M13: 0.78081113 | N13: 238.93048 | O13: 10.191051 | P13: 0.47999999 | Q13: 17.448921 | R13: 0.48598662 | S13: 1000.0676 | T13: 706.22223
B14: ="CRS22WW7201249" -> CRS22WW7201249 | C14: 45757 | D14: 0.67070602 | E14: I->V | F14: 384 | G14: 4 | H14: 384.38776 | I14: 10.140449 | J14: 49.486633 | K14: 9.2132359 | L14: 41.721252 | M14: 0.7659924 | N14: 234.95584 | O14: 10.073732 | P14: 0.47999999 | Q14: 17.463585 | R14: 0.47899735 | S14: 1000.003 | T14: 908.57416
B15: ="CRS25BT114A00266" -> CRS25BT114A00266 | C15: 45938 | D15: 0.89993056 | E15: I->V | F15: 447 | G15: 3 | H15: 447.3429 | I15: 11.401231 | J15: 49.769432 | K15: 10.802318 | L15: 41.411751 | M15: 0.7883628 | N15: 21.763216 | O15: 21.737803 | P15: 21.5625 | Q15: 0.63180506 | R15: 999.65375 | S15: 314.54868
B16: ="CRS25BT114A00269" -> CRS25BT114A00269 | C16: 45938 | D16: 0.89778935 | E16: I->V | F16: 454 | G16: 3 | H16: 454.92426 | I16: 11.304819 | J16: 49.725563 | K16: 10.766623 | L16: 42.253197 | M16: 0.80927432 | N16: 22.132048 | O16: 21.594019 | P16: 21.625 | Q16: 0.44909337 | R16: 1000.2782 | S16: 442.94989
B17: ="CRS25BT14400031" -> CRS25BT14400031 | C17: 45938 | D17: 0.11802083 | E17: I->V | F17: 454 | G17: 3 | H17: 454.94101 | I17: 11.422936 | J17: 50.236458 | K17: 10.798207 | L17: 42.131161 | M17: 0.79279029 | N17: 22.132864 | O17: 22.468903 | P17: 22.75 | Q17: 0.73327351 | R17: 1000.5062 | S17: 521.85669
B18: ="CRS25BT144000982" -> CRS25BT144000982 | C18: 45932 | D18: 0.7966088 | E18: I->V | F18: 459 | G18: 3 | H18: 459.47531 | I18: 11.126241 | J18: 49.941364 | K18: 10.825412 | L18: 42.444145 | M18: 0.82690066 | N18: 22.353456 | O18: 23.774509 | P18: 24.3125 | Q18: 0.54982799 | R18: 1000.1462 | S18: 672.50024
B19: ="CRS25BT14400183" -> CRS25BT14400183 | C19: 45938 | D19: 0.12556713 | E19: I->V | F19: 450 | G19: 3 | H19: 450.96268 | I19: 11.249041 | J19: 49.812984 | K19: 10.642557 | L19: 42.373528 | M19: 0.80478996 | N19: 21.939318 | O19: 22.189951 | P19: 22.625 | Q19: 0.4821057 | R19: 999.91589 | S19: 466.35056
B20: ="CRS25BT144A" -> CRS25BT144A | C20: 45932 | D20: 0.80971065 | E20: I->V | F20: 454 | G20: 3 | H20: 454.38068 | I20: 11.168302 | J20: 49.86462 | K20: 10.680544 | L20: 42.542843 | M20: 0.81590617 | N20: 22.105604 | O20: 23.480392 | P20: 24.25 | Q20: 0.57017261 | R20: 1000.1749 | S20: 536.43079
B21: ="CRS25BT144A00001" -> CRS25BT144A00001 | C21: 45931 | D21: 0.89686343 | E21: I->V | F21: 449 | G21: 3 | H21: 449.14935 | I21: 11.240789 | J21: 49.813217 | K21: 10.646033 | L21: 42.189362 | M21: 0.80213851 | N21: 21.851099 | O21: 23.44976 | P21: 24.1875 | Q21: 0.54077083 | R21: 999.88629 | S21: 552.12543
B22: ="CRS25BT144A0000330" -> CRS25BT144A0000330 | C22: 45939 | D22: 0.073310185 | E22: I->V | F22: 449 | G22: 3 | H22: 449.63098 | I22: 11.313531 | J22: 49.675705 | K22: 10.646861 | L22: 42.231316 | M22: 0.8000443 | N22: 21.874531 | O22: 21.843138 | P22: 21.5625 | Q22: 0.41164762 | R22: 1000.3057 | S22: 350.77722
B23: ="CRS25BT144A0000337" -> CRS25BT144A0000337 | C23: 45939 | D23: 0.075162037 | E23: I->V | F23: 302 | G23: 1 | H23: 302.51096 | I23: 11.131072 | J23: 39.104042 | K23: 10.071512 | L23: 30.036301 | M23: 0.69499624 | N23: 14.717147 | O23: 21.964466 | P23: 21.5625 | Q23: 1e-06 | R23: 1000.2949 | S23: 223.50926
B24: ="CRS25BT144A00009" -> CRS25BT144A00009 | C24: 45931 | D24: 0.91956019 | E24: I->V | F24: 459 | G24: 3 | H24: 459.64172 | I24: 11.24736 | J24: 49.757046 | K24: 10.802536 | L24: 42.549427 | M24: 0.82132351 | N24: 22.361553 | O24: 23.343395 | P24: 24.0625 | Q24: 0.91783088 | R24: 1000.2292 | S24: 594.89349
B25: ="CRS25BT144A00011" -> CRS25BT144A00011 | C25: 45931 | D25: 0.9225463 | E25: I->V | F25: 459 | G25: 3 | H25: 459.56479 | I25: 11.25167 | J25: 49.795418 | K25: 10.747291 | L25: 42.76099 | M25: 0.82023895 | N25: 22.357811 | O25: 23.451469 | P25: 24.0625 | Q25: 0.44076991 | R25: 1000.2415 | S25: 591.09998
B26: ="CRS25BT144A00012" -> CRS25BT144A00012 | C26: 45931 | D26: 0.91873843 | E26: I->V | F26: 456 | G26: 3 | H26: 456.83066 | I26: 11.374182 | J26: 49.554005 | K26: 10.806236 | L26: 42.274723 | M26: 0.81050617 | N26: 22.224794 | O26: 23.464724 | P26: 24.0625 | Q26: 1.0724149 | R26: 1000.1872 | S26: 550.87799
B27: ="CRS25BT144A00013" -> CRS25BT144A00013 | C27: 45931 | D27: 0.91697917 | E27: I->V | F27: 454 | G27: 3 | H27: 454.93689 | I27: 11.391588 | J27: 49.816917 | K27: 10.792012 | L27: 42.154964 | M27: 0.80165964 | N27: 22.132664 | O27: 23.450985 | P27: 24.0625 | Q27: 0.49599949 | R27: 999.62189 | S27: 563.65753
B28: ="CRS25BT144A00015" -> CRS25BT144A00015 | C28: 45931 | D28: 0.92131944 | E28: I->V | F28: 458 | G28: 3 | H28: 458.20731 | I28: 11.406261 | J28: 49.810318 | K28: 10.852518 | L28: 42.221287 | M28: 0.80649072 | N28: 22.291769 | O28: 23.42868 | P28: 24.0625 | Q28: 0.59233528 | R28: 1000.2145 | S28: 564.39764
B29: ="CRS25BT144A00016" -> CRS25BT144A00016 | C29: 45931 | D29: 0.92378472 | E29: I->V | F29: 460 | G29: 3 | H29: 460.92755 | I29: 11.427643 | J29: 49.782104 | K29: 10.916114 | L29: 42.22451 | M29: 0.81021965 | N29: 22.424109 | O29: 23.490242 | P29: 24.0625 | Q29: 0.70894581 | R29: 999.66974 | S29: 549.22583
B30: ="CRS25BT144A00019" -> CRS25BT144A00019 | C30: 45931 | D30: 0.89274306 | E30: I->V | F30: 447 | G30: 3 | H30: 447.45755 | I30: 11.23774 | J30: 49.812172 | K30: 10.572264 | L30: 42.323723 | M30: 0.7993508 | N30: 21.768793 | O30: 23.529655 | P30: 24.1875 | Q30: 0.47462633 | R30: 1000.0449 | S30: 544.9657
B31: ="CRS25BT144A00020" -> CRS25BT144A00020 | C31: 45931 | D31: 0.86895833 | E31: I->V | F31: 441 | G31: 3 | H31: 441.15875 | I31: 11.163874 | J31: 49.80526 | K31: 10.534636 | L31: 41.876984 | M31: 0.793423 | N31: 21.462357 | O31: 23.717524 | P31: 24.3125 | Q31: 0.48756978 | R31: 1000.0677 | S31: 598.09998
B32: ="CRS25BT144A00021" -> CRS25BT144A00021 | C32: 45931 | D32: 0.86700231 | E32: I->V | F32: 445 | G32: 3 | H32: 445.92651 | I32: 11.19967 | J32: 49.798141 | K32: 10.58745 | L32: 42.118408 | M32: 0.79954875 | N32: 21.694309 | O32: 23.808384 | P32: 24.3125 | Q32: 0.44877887 | R32: 1000.0318 | S32: 568.17938
B33: ="CRS25BT144A00024" -> CRS25BT144A00024 | C33: 45931 | D33: 0.98958333 | E33: I->V | F33: 464 | G33: 3 | H33: 464.0217 | I33: 11.432629 | J33: 49.742512 | K33: 10.876603 | L33: 42.662373 | M33: 0.81595176 | N33: 22.574638 | O33: 24.276001 | P33: 24.375 | Q33: 0.44420746 | R33: 999.04846 | S33: 582.47516
B34: ="CRS25BT144A00025" -> CRS25BT144A00025 | C34: 45931 | D34: 0.96643519 | E34: I->V | F34: 451 | G34: 3 | H34: 451.02271 | I34: 11.437407 | J34: 49.782932 | K34: 10.844535 | L34: 41.589863 | M34: 0.79211891 | N34: 21.942238 | O34: 23.837053 | P34: 24.1875 | Q34: 0.82510436 | R34: 999.82147 | S34: 512.07733
B35: ="CRS25BT144A00026" -> CRS25BT144A00026 | C35: 45931 | D35: 0.96065972 | E35: I->V | F35: 465 | G35: 3 | H35: 465.25082 | I35: 11.48068 | J35: 49.87907 | K35: 10.941373 | L35: 42.522163 | M35: 0.81245846 | N35: 22.634436 | O35: 24.075151 | P35: 24.125 | Q35: 0.49274424 | R35: 1000.4846 | S35: 555.2948
B36: ="CRS25BT144A00027" -> CRS25BT144A00027 | C36: 45931 | D36: 0.93420139 | E36: I->V | F36: 460 | G36: 3 | H36: 460.30527 | I36: 11.372624 | J36: 49.789112 | K36: 10.824642 | L36: 42.523834 | M36: 0.8129257 | N36: 22.393835 | O36: 24.067987 | P36: 24 | Q36: 0.46683812 | R36: 1000.9404 | S36: 576.23694
B37: ="CRS25BT144A00028" -> CRS25BT144A00028 | C37: 45931 | D37: 0.93335648 | E37: I->V | F37: 461 | G37: 3 | H37: 461.93271 | I37: 11.29239 | J37: 49.845222 | K37: 10.888803 | L37: 42.422729 | M37: 0.82067144 | N37: 22.473009 | O37: 23.903234 | P37: 24 | Q37: 0.53909737 | R37: 1000.2413 | S37: 663.41449
B38: ="CRS25BT144A00029" -> CRS25BT144A00029 | C38: 45931 | D38: 0.95701389 | E38: I->V | F38: 453 | G38: 3 | H38: 453.69598 | I38: 11.453023 | J38: 49.775307 | K38: 10.820201 | L38: 41.930458 | M38: 0.79584932 | N38: 22.072292 | O38: 23.890089 | P38: 24.125 | Q38: 0.50716048 | R38: 999.20502 | S38: 525.33246
B39: ="CRS25BT144A00030" -> CRS25BT144A00030 | C39: 45931 | D39: 0.95597222 | E39: I->V | F39: 453 | G39: 3 | H39: 453.97986 | I39: 11.399604 | J39: 49.830681 | K39: 10.838794 | L39: 41.884724 | M39: 0.79918993 | N39: 22.086103 | O39: 24.005081 | P39: 24.0625 | Q39: 0.69343942 | R39: 1000.497 | S39: 543.17957
B40: ="CRS25BT144A00031" -> CRS25BT144A00031 | C40: 45931 | D40: 0.93125 | E40: I->V | F40: 461 | G40: 3 | H40: 461.96033 | I40: 11.449556 | J40: 49.80896 | K40: 10.883386 | L40: 42.446377 | M40: 0.81004387 | N40: 22.474354 | O40: 23.889519 | P40: 24 | Q40: 0.45497775 | R40: 1000.2147 | S40: 574.40924
...

Sheet SPECIAL CODES
A1: A1 | B1: 390BB
A2: B1 | B2: 385WW
A3: C1 | B3: 390WW
A4: D1 | B4: 395WW
B5: made in 2022 sold in 2023
B6: CERT PANEL
